Workbook

Sheet Master
Q1: Date | S1: Comments
A2: Tank | B2: Section | C2: Treatment | D2: Species | E2: BeeTag ID | F2: Unique_ID | G2: Weight (g) | H2: Length (mm) | I2: Width (mm) | J2: Depth (mm) | K2: Weight (g) | L2: Length (mm) | M2: Width (mm) | N2: Depth (mm) | O2: Ripe? | R2: Dry Shell (g) | U2: Balance: Shizmadu UP423X d=0.001g,UniBloc
A3: 1 | B3: 1 | C3: Warm | D3: Oyster | E3: W42 | F3: O_W42 | G3: 19.64 | H3: 73 | I3: 37.32 | J3: 12.43 | K3: 19.406 | L3: 72.88 | M3: 33.65 | N3: 16.19 | P3: 45886 | Q3: 45886 | U3: 02 Jul 25 Moved oysters and mussels to boxes
A4: 1 | B4: 1 | C4: Warm | D4: Oyster | E4: B61 | F4: O_B61 | G4: 35.547 | H4: 73.82 | I4: 54.05 | J4: 14.88 | K4: 35.465 | L4: 75.17 | M4: 50.24 | N4: 19.13 | P4: 45879 | Q4: 45879 | U4: 03 Jul 25 Moved scallops to boxes
A5: 1 | B5: 1 | C5: Warm | D5: Oyster | E5: B54 | F5: O_B54 | G5: 30.829 | H5: =IFERROR(INDEX('Tagging key'!D:D, MATCH(F5,'Tagging key'!C:C,0)),"") -> 72.75 | I5: =IFERROR(INDEX('Tagging key'!E:E, MATCH(F5,'Tagging key'!C:C,0)),"") -> 42.12 | J5: =IFERROR(INDEX('Tagging key'!F:F, MATCH(F5,'Tagging key'!C:C,0)),"") -> 16.44 | K5: 30.754 | L5: 67.887 | M5: 36.02 | N5: 11.71 | P5: 45877 | Q5: 45877
A6: 1 | B6: 1 | C6: Warm | D6: Oyster | E6: R42 | F6: O_R42 | G6: 32.083 | H6: =IFERROR(INDEX('Tagging key'!D:D, MATCH(F6,'Tagging key'!C:C,0)),"") -> 63.69 | I6: =IFERROR(INDEX('Tagging key'!E:E, MATCH(F6,'Tagging key'!C:C,0)),"") -> 53.55 | J6: =IFERROR(INDEX('Tagging key'!F:F, MATCH(F6,'Tagging key'!C:C,0)),"") -> 18.02 | K6: 32.183 | L6: 63.77 | M6: 53.09 | N6: 19.13 | P6: 45882 | Q6: 45882 | R6: 22.071
A7: 1 | B7: 2 | C7: Warm | D7: Oyster | E7: B68 | F7: O_B68 | G7: 20.537 | H7: =IFERROR(INDEX('Tagging key'!D:D, MATCH(F7,'Tagging key'!C:C,0)),"") -> 59.48 | I7: =IFERROR(INDEX('Tagging key'!E:E, MATCH(F7,'Tagging key'!C:C,0)),"") -> 42.39 | J7: =IFERROR(INDEX('Tagging key'!F:F, MATCH(F7,'Tagging key'!C:C,0)),"") -> 13.12 | K7: 20.258 | L7: 58.38 | M7: 39.17 | N7: 14.78 | P7: 45882 | Q7: 45882 | R7: 11.349
A8: 1 | B8: 2 | C8: Warm | D8: Oyster | E8: B65 | F8: O_B65 | G8: 87.494 | H8: =IFERROR(INDEX('Tagging key'!D:D, MATCH(F8,'Tagging key'!C:C,0)),"") -> 69.63 | I8: =IFERROR(INDEX('Tagging key'!E:E, MATCH(F8,'Tagging key'!C:C,0)),"") -> 70.35 | J8: =IFERROR(INDEX('Tagging key'!F:F, MATCH(F8,'Tagging key'!C:C,0)),"") -> 23.62 | K8: 86.667 | L8: 73.01 | M8: 64.85 | N8: 21.42 | P8: 45877 | Q8: 45877 | S8: Removed a double
A9: 1 | B9: 2 | C9: Warm | D9: Oyster | E9: B5 | F9: O_B5 | G9: 29.658 | H9: =IFERROR(INDEX('Tagging key'!D:D, MATCH(F9,'Tagging key'!C:C,0)),"") -> 72.69 | I9: =IFERROR(INDEX('Tagging key'!E:E, MATCH(F9,'Tagging key'!C:C,0)),"") -> 44.55 | J9: =IFERROR(INDEX('Tagging key'!F:F, MATCH(F9,'Tagging key'!C:C,0)),"") -> 14.49 | K9: 29.744 | L9: 71.61 | M9: 44.79 | N9: 16.88 | P9: 45879 | Q9: 45879 | S9: Was in box 3
A10: 1 | B10: 2 | C10: Warm | D10: Oyster | E10: B88 | F10: O_B88 | G10: 28.24 | H10: =IFERROR(INDEX('Tagging key'!D:D, MATCH(F10,'Tagging key'!C:C,0)),"") -> 66.35 | I10: =IFERROR(INDEX('Tagging key'!E:E, MATCH(F10,'Tagging key'!C:C,0)),"") -> 50.23 | J10: =IFERROR(INDEX('Tagging key'!F:F, MATCH(F10,'Tagging key'!C:C,0)),"") -> 14.63 | K10: 28.046 | L10: 65.13 | M10: 47.82 | N10: 17.97 | P10: 45879 | Q10: 45879
A11: 1 | B11: 3 | C11: Warm | D11: Oyster | E11: R49 | F11: O_R49 | G11: 33.59 | H11: =IFERROR(INDEX('Tagging key'!D:D, MATCH(F11,'Tagging key'!C:C,0)),"") -> 62.02 | I11: =IFERROR(INDEX('Tagging key'!E:E, MATCH(F11,'Tagging key'!C:C,0)),"") -> 43.46 | J11: =IFERROR(INDEX('Tagging key'!F:F, MATCH(F11,'Tagging key'!C:C,0)),"") -> 17.31 | K11: 33.459 | L11: 62.33 | M11: 44.03 | N11: 17.73 | P11: 45886 | Q11: 45886
A12: 1 | B12: 3 | C12: Warm | D12: Oyster | E12: W15 | F12: O_W15 | G12: 42.011 | H12: =IFERROR(INDEX('Tagging key'!D:D, MATCH(F12,'Tagging key'!C:C,0)),"") -> 76.48 | I12: =IFERROR(INDEX('Tagging key'!E:E, MATCH(F12,'Tagging key'!C:C,0)),"") -> 44.98 | J12: =IFERROR(INDEX('Tagging key'!F:F, MATCH(F12,'Tagging key'!C:C,0)),"") -> 20.4 | K12: 41.79 | L12: 70.64 | M12: 39.33 | N12: 14.93 | P12: 45877 | Q12: 45877
A13: 1 | B13: 3 | C13: Warm | D13: Oyster | E13: B92 | F13: O_B92 | G13: 29.664 | H13: =IFERROR(INDEX('Tagging key'!D:D, MATCH(F13,'Tagging key'!C:C,0)),"") -> 67.87 | I13: =IFERROR(INDEX('Tagging key'!E:E, MATCH(F13,'Tagging key'!C:C,0)),"") -> 51.68 | J13: =IFERROR(INDEX('Tagging key'!F:F, MATCH(F13,'Tagging key'!C:C,0)),"") -> 14.59 | K13: 29.542 | L13: 66.76 | M13: 46.35 | N13: 17.4 | P13: 45886 | Q13: 45886 | S13: Was in box 2
A14: 1 | B14: 3 | C14: Warm | D14: Oyster | E14: B91 | F14: O_B91 | G14: 34.233 | H14: =IFERROR(INDEX('Tagging key'!D:D, MATCH(F14,'Tagging key'!C:C,0)),"") -> 66.29 | I14: =IFERROR(INDEX('Tagging key'!E:E, MATCH(F14,'Tagging key'!C:C,0)),"") -> 47.34 | J14: =IFERROR(INDEX('Tagging key'!F:F, MATCH(F14,'Tagging key'!C:C,0)),"") -> 15.65 | K14: 34.229 | L14: 66.77 | M14: 48.18 | N14: 19.8 | P14: 45882 | Q14: 45882 | R14: 21.574
A15: 1 | B15: 4 | C15: Warm | D15: Mussel | E15: G30 | F15: M_G30 | G15: 82.3 | H15: =IFERROR(INDEX('Tagging key'!D:D, MATCH(F15,'Tagging key'!C:C,0)),"") -> 96 | I15: =IFERROR(INDEX('Tagging key'!E:E, MATCH(F15,'Tagging key'!C:C,0)),"") -> 46 | J15: =IFERROR(INDEX('Tagging key'!F:F, MATCH(F15,'Tagging key'!C:C,0)),"") -> 37 | K15: 82.115 | L15: 98.74 | M15: 47.44 | N15: 36.25 | P15: 45882 | Q15: 45882 | R15: 23.783
A16: 1 | B16: 4 | C16: Warm | D16: Mussel | E16: B31 | F16: M_B31 | G16: 41.288 | H16: =IFERROR(INDEX('Tagging key'!D:D, MATCH(F16,'Tagging key'!C:C,0)),"") -> 75.98 | I16: =IFERROR(INDEX('Tagging key'!E:E, MATCH(F16,'Tagging key'!C:C,0)),"") -> 40.25 | J16: =IFERROR(INDEX('Tagging key'!F:F, MATCH(F16,'Tagging key'!C:C,0)),"") -> 27.05 | K16: 41.254 | L16: 70.85 | M16: 33.99 | N16: 23.42 | P16: 45877 | Q16: 45877
A17: 1 | B17: 4 | C17: Warm | D17: Mussel | E17: B67 | F17: M_B67 | G17: 79.137 | H17: =IFERROR(INDEX('Tagging key'!D:D, MATCH(F17,'Tagging key'!C:C,0)),"") -> 92.37 | I17: =IFERROR(INDEX('Tagging key'!E:E, MATCH(F17,'Tagging key'!C:C,0)),"") -> 47.28 | J17: =IFERROR(INDEX('Tagging key'!F:F, MATCH(F17,'Tagging key'!C:C,0)),"") -> 34.01 | K17: 78.926 | L17: 94.2 | M17: 45.59 | N17: 37.21 | P17: 45879 | Q17: 45879
A18: 1 | B18: 4 | C18: Warm | D18: Mussel | E18: R28 | F18: M_R28 | G18: 37.579 | H18: =IFERROR(INDEX('Tagging key'!D:D, MATCH(F18,'Tagging key'!C:C,0)),"") -> 74.19 | I18: =IFERROR(INDEX('Tagging key'!E:E, MATCH(F18,'Tagging key'!C:C,0)),"") -> 38.65 | J18: =IFERROR(INDEX('Tagging key'!F:F, MATCH(F18,'Tagging key'!C:C,0)),"") -> 27.59 | K18: 38.648 | L18: 74.26 | M18: 34.49 | N18: 28.23 | P18: 45886 | Q18: 45886
A19: 1 | B19: 5 | C19: Warm | D19: Mussel | E19: R82 | F19: M_R82 | G19: 42.545 | H19: =IFERROR(INDEX('Tagging key'!D:D, MATCH(F19,'Tagging key'!C:C,0)),"") -> 81 | I19: =IFERROR(INDEX('Tagging key'!E:E, MATCH(F19,'Tagging key'!C:C,0)),"") -> 41 | J19: =IFERROR(INDEX('Tagging key'!F:F, MATCH(F19,'Tagging key'!C:C,0)),"") -> 28 | K19: 48.897 | L19: 82.36 | M19: 40.42 | N19: 28.98 | P19: 45879 | Q19: 45879
A20: 1 | B20: 5 | C20: Warm | D20: Mussel | E20: B52 | F20: M_B52 | G20: 41.808 | H20: =IFERROR(INDEX('Tagging key'!D:D, MATCH(F20,'Tagging key'!C:C,0)),"") -> 77.14 | I20: =IFERROR(INDEX('Tagging key'!E:E, MATCH(F20,'Tagging key'!C:C,0)),"") -> 41.67 | J20: =IFERROR(INDEX('Tagging key'!F:F, MATCH(F20,'Tagging key'!C:C,0)),"") -> 27.56 | K20: 42.925 | L20: 73.25 | M20: 33.22 | N20: 22.36 | P20: 45877 | Q20: 45877
A21: 1 | B21: 5 | C21: Warm | D21: Mussel | E21: B93 | F21: M_B93 | G21: 48.348 | H21: =IFERROR(INDEX('Tagging key'!D:D, MATCH(F21,'Tagging key'!C:C,0)),"") -> 77 | I21: =IFERROR(INDEX('Tagging key'!E:E, MATCH(F21,'Tagging key'!C:C,0)),"") -> 39 | J21: =IFERROR(INDEX('Tagging key'!F:F, MATCH(F21,'Tagging key'!C:C,0)),"") -> 31 | K21: 59.117 | L21: 78.35 | M21: 39.34 | N21: 31.23 | P21: 45882 | Q21: 45882 | R21: 26.2
A22: 1 | B22: 5 | C22: Warm | D22: Mussel | E22: G1 | F22: M_G1 | G22: 46.31 | H22: =IFERROR(INDEX('Tagging key'!D:D, MATCH(F22,'Tagging key'!C:C,0)),"") -> 78 | I22: =IFERROR(INDEX('Tagging key'!E:E, MATCH(F22,'Tagging key'!C:C,0)),"") -> 40 | J22: =IFERROR(INDEX('Tagging key'!F:F, MATCH(F22,'Tagging key'!C:C,0)),"") -> 26 | K22: 47.335 | L22: 81.04 | M22: 40.92 | N22: 26.14 | P22: 45886 | Q22: 45886
A23: 1 | B23: 6 | C23: Warm | D23: Mussel | E23: G51 | F23: M_G51 | G23: 23.08 | H23: =IFERROR(INDEX('Tagging key'!D:D, MATCH(F23,'Tagging key'!C:C,0)),"") -> 62.3 | I23: =IFERROR(INDEX('Tagging key'!E:E, MATCH(F23,'Tagging key'!C:C,0)),"") -> 34.5 | J23: =IFERROR(INDEX('Tagging key'!F:F, MATCH(F23,'Tagging key'!C:C,0)),"") -> 21.4 | K23: 23.276 | L23: 63.05 | M23: 34.99 | N23: 22.39 | P23: 45879 | Q23: 45879 | S23: B47 Died 7/10, replaced with G51
A24: 1 | B24: 6 | C24: Warm | D24: Mussel | E24: B51 | F24: M_B51 | G24: 45.984 | H24: =IFERROR(INDEX('Tagging key'!D:D, MATCH(F24,'Tagging key'!C:C,0)),"") -> 76.72 | I24: =IFERROR(INDEX('Tagging key'!E:E, MATCH(F24,'Tagging key'!C:C,0)),"") -> 42.05 | J24: =IFERROR(INDEX('Tagging key'!F:F, MATCH(F24,'Tagging key'!C:C,0)),"") -> 26.28 | K24: 46.108 | L24: 71.5 | M24: 36.06 | N24: 21.64 | P24: 45877 | Q24: 45877
A25: 1 | B25: 6 | C25: Warm | D25: Mussel | E25: B69 | F25: M_B69 | G25: 31.393 | H25: =IFERROR(INDEX('Tagging key'!D:D, MATCH(F25,'Tagging key'!C:C,0)),"") -> 68 | I25: =IFERROR(INDEX('Tagging key'!E:E, MATCH(F25,'Tagging key'!C:C,0)),"") -> 33 | J25: =IFERROR(INDEX('Tagging key'!F:F, MATCH(F25,'Tagging key'!C:C,0)),"") -> 26 | K25: 31.966 | L25: 69.74 | M25: 34.26 | N25: 26.15 | P25: 45882 | Q25: 45882 | R25: 11.113
A26: 1 | B26: 6 | C26: Warm | D26: Mussel | E26: B94 | F26: M_B94 | G26: 51.927 | H26: =IFERROR(INDEX('Tagging key'!D:D, MATCH(F26,'Tagging key'!C:C,0)),"") -> 79 | I26: =IFERROR(INDEX('Tagging key'!E:E, MATCH(F26,'Tagging key'!C:C,0)),"") -> 37 | J26: =IFERROR(INDEX('Tagging key'!F:F, MATCH(F26,'Tagging key'!C:C,0)),"") -> 32 | K26: 52.339 | L26: 79.34 | M26: 37.27 | N26: 32.94 | P26: 45886 | Q26: 45886
A27: 1 | B27: 7 | C27: Warm | D27: Scallop | E27: Y32 | F27: S_Y32 | G27: 50.988 | H27: =IFERROR(INDEX('Tagging key'!D:D, MATCH(F27,'Tagging key'!C:C,0)),"") -> 69 | I27: =IFERROR(INDEX('Tagging key'!E:E, MATCH(F27,'Tagging key'!C:C,0)),"") -> 71.5 | J27: =IFERROR(INDEX('Tagging key'!F:F, MATCH(F27,'Tagging key'!C:C,0)),"") -> 18 | K27: 46.064 | L27: 69.92 | M27: 73.16 | N27: 21 | P27: 45882 | Q27: 45882 | R27: 23.565
A28: 1 | B28: 7 | C28: Warm | D28: Scallop | E28: G70 | F28: S_G70 | G28: 50.64 | H28: =IFERROR(INDEX('Tagging key'!D:D, MATCH(F28,'Tagging key'!C:C,0)),"") -> 71 | I28: =IFERROR(INDEX('Tagging key'!E:E, MATCH(F28,'Tagging key'!C:C,0)),"") -> 73 | J28: =IFERROR(INDEX('Tagging key'!F:F, MATCH(F28,'Tagging key'!C:C,0)),"") -> 20 | K28: 40.579 | L28: 70.88 | M28: 74.32 | N28: 21.2 | P28: 45886 | Q28: 45886 | S28: Was in as G79
A29: 1 | B29: 7 | C29: Warm | D29: Scallop | E29: Y54 | F29: S_Y54 | G29: 57.49 | H29: =IFERROR(INDEX('Tagging key'!D:D, MATCH(F29,'Tagging key'!C:C,0)),"") -> 71.5 | I29: =IFERROR(INDEX('Tagging key'!E:E, MATCH(F29,'Tagging key'!C:C,0)),"") -> 75.5 | J29: =IFERROR(INDEX('Tagging key'!F:F, MATCH(F29,'Tagging key'!C:C,0)),"") -> 20 | K29: 55.155 | L29: 73.62 | M29: 78.32 | N29: 23.12 | P29: 45879 | Q29: 45879 | R29: 20.813
A30: 1 | B30: 7 | C30: Warm | D30: Scallop | E30: Y74 | F30: S_Y74 | G30: 46.17 | H30: =IFERROR(INDEX('Tagging key'!D:D, MATCH(F30,'Tagging key'!C:C,0)),"") -> 66 | I30: =IFERROR(INDEX('Tagging key'!E:E, MATCH(F30,'Tagging key'!C:C,0)),"") -> 70 | J30: =IFERROR(INDEX('Tagging key'!F:F, MATCH(F30,'Tagging key'!C:C,0)),"") -> 17 | K30: 43.563 | L30: 63.06 | M30: 65.51 | N30: 14.5 | P30: 45877 | Q30: 45877
A31: 1 | B31: 8 | C31: Warm | D31: Scallop | E31: Y71 | F31: S_Y71 | G31: 70.19 | H31: =IFERROR(INDEX('Tagging key'!D:D, MATCH(F31,'Tagging key'!C:C,0)),"") -> 77 | I31: =IFERROR(INDEX('Tagging key'!E:E, MATCH(F31,'Tagging key'!C:C,0)),"") -> 80 | J31: =IFERROR(INDEX('Tagging key'!F:F, MATCH(F31,'Tagging key'!C:C,0)),"") -> 20 | K31: 66.168 | L31: 78.34 | M31: 81.95 | N31: 22.6 | P31: 45882 | Q31: 45882 | R31: 33.409
A32: 1 | B32: 8 | C32: Warm | D32: Scallop | E32: W57 | F32: S_W57 | G32: 43.73 | H32: =IFERROR(INDEX('Tagging key'!D:D, MATCH(F32,'Tagging key'!C:C,0)),"") -> 67 | I32: =IFERROR(INDEX('Tagging key'!E:E, MATCH(F32,'Tagging key'!C:C,0)),"") -> 70 | J32: =IFERROR(INDEX('Tagging key'!F:F, MATCH(F32,'Tagging key'!C:C,0)),"") -> 13 | K32: 40.048 | L32: 67.84 | M32: 71.9 | N32: 17.36 | P32: 45886 | Q32: 45886
A33: 1 | B33: 8 | C33: Warm | D33: Scallop | E33: G37 | F33: S_G37 | G33: 45.28 | H33: =IFERROR(INDEX('Tagging key'!D:D, MATCH(F33,'Tagging key'!C:C,0)),"") -> 69.62 | I33: =IFERROR(INDEX('Tagging key'!E:E, MATCH(F33,'Tagging key'!C:C,0)),"") -> 70.99 | J33: =IFERROR(INDEX('Tagging key'!F:F, MATCH(F33,'Tagging key'!C:C,0)),"") -> 17.56 | K33: 43.895 | L33: 66.21 | M33: 69.48 | N33: 14.26 | P33: 45877 | Q33: 45877
A34: 1 | B34: 8 | C34: Warm | D34: Scallop | E34: G50 | F34: S_G50 | G34: 46.96 | H34: =IFERROR(INDEX('Tagging key'!D:D, MATCH(F34,'Tagging key'!C:C,0)),"") -> 76 | I34: =IFERROR(INDEX('Tagging key'!E:E, MATCH(F34,'Tagging key'!C:C,0)),"") -> 74 | J34: =IFERROR(INDEX('Tagging key'!F:F, MATCH(F34,'Tagging key'!C:C,0)),"") -> 16.54 | K34: 43.487 | L34: 72.25 | M34: 70.2 | N34: 19 | P34: 45879 | Q34: 45879
A35: 1 | B35: 9 | C35: Warm | D35: Scallop | E35: B3 | F35: S_B3 | H35: =IFERROR(INDEX('Tagging key'!D:D, MATCH(F35,'Tagging key'!C:C,0)),"") | I35: =IFERROR(INDEX('Tagging key'!E:E, MATCH(F35,'Tagging key'!C:C,0)),"") | J35: =IFERROR(INDEX('Tagging key'!F:F, MATCH(F35,'Tagging key'!C:C,0)),"") | K35: 63.925 | L35: 74.74 | M35: 79.15 | N35: 15.8 | P35: 45877 | Q35: 45877 | S35: Y10 Died 7/10 | T35: G55B Died 7/14
A36: 1 | B36: 9 | C36: Warm | D36: Scallop | E36: B4 | F36: S_B4 | H36: =IFERROR(INDEX('Tagging key'!D:D, MATCH(F36,'Tagging key'!C:C,0)),"") | I36: =IFERROR(INDEX('Tagging key'!E:E, MATCH(F36,'Tagging key'!C:C,0)),"") | J36: =IFERROR(INDEX('Tagging key'!F:F, MATCH(F36,'Tagging key'!C:C,0)),"") | K36: 64.118 | L36: 79.66 | M36: 84.5 | N36: 21.52 | P36: 45879 | Q36: 45879 | S36: Y93 Died 7/10 | T36: G46B Died 7/14
A37: 1 | B37: 9 | C37: Warm | D37: Scallop | E37: B2 | F37: S_B2 | H37: =IFERROR(INDEX('Tagging key'!D:D, MATCH(F37,'Tagging key'!C:C,0)),"") | I37: =IFERROR(INDEX('Tagging key'!E:E, MATCH(F37,'Tagging key'!C:C,0)),"") | J37: =IFERROR(INDEX('Tagging key'!F:F, MATCH(F37,'Tagging key'!C:C,0)),"") | K37: 48.91 | L37: 71.35 | M37: 75.45 | N37: 19.71 | P37: 45882 | Q37: 45882 | T37: G34 Died 7/13
A38: 1 | B38: 9 | C38: Warm | D38: Scallop | E38: B1 | F38: S_B1 | H38: =IFERROR(INDEX('Tagging key'!D:D, MATCH(F38,'Tagging key'!C:C,0)),"") | I38: =IFERROR(INDEX('Tagging key'!E:E, MATCH(F38,'Tagging key'!C:C,0)),"") | J38: =IFERROR(INDEX('Tagging key'!F:F, MATCH(F38,'Tagging key'!C:C,0)),"") | K38: 57.301 | L38: 75.94 | M38: 81.98 | N38: 23 | P38: 45886 | Q38: 45886 | S38: G62 Died 7/10 | T38: G45B Died 7/13
A39: 2 | B39: 1 | C39: Multi | D39: Oyster | E39: W4 | F39: O_W4 | G39: 27.457 | H39: 66.92 | I39: 40.6 | J39: 14.18 | K39: 27.447 | L39: 66.41 | M39: 40.3 | N39: 15.3 | P39: 45886 | Q39: 45886
A40: 2 | B40: 1 | C40: Multi | D40: Oyster | E40: B100 | F40: O_B100 | G40: 28.461 | H40: =IFERROR(INDEX('Tagging key'!D:D, MATCH(F40,'Tagging key'!C:C,0)),"") -> 60 | I40: =IFERROR(INDEX('Tagging key'!E:E, MATCH(F40,'Tagging key'!C:C,0)),"") -> 48.92 | J40: =IFERROR(INDEX('Tagging key'!F:F, MATCH(F40,'Tagging key'!C:C,0)),"") -> 17.08 | K40: 28.301 | L40: 61 | M40: 46.24 | N40: 18.86 | P40: 45882 | Q40: 45882 | R40: 19.264
...

Sheet Master Renamed
A1: Tank | B1: Section | C1: Treatment | D1: Species | E1: BeeTag_ID | F1: Unique_ID | G1: Before_Weight_(g) | H1: Before_Length_(mm) | I1: Before_Width_(mm) | J1: Before_Depth_(mm) | K1: After_Weight_(g) | L1: After_Length_(mm) | M1: After_Width_(mm) | N1: After_Depth_(mm) | O1: Ripe? | Q1: Date | R1: Dry_Shell_(g) | S1: Comments
A2: 1 | B2: 1 | C2: Warm | D2: Oyster | E2: W42 | F2: O_W42 | G2: 19.64 | H2: 73 | I2: 37.32 | J2: 12.43 | K2: 19.406 | L2: 72.88 | M2: 33.65 | N2: 16.19 | P2: 45886 | Q2: 45886 | U2: 02 Jul 25 Moved oysters and mussels to boxes
A3: 1 | B3: 1 | C3: Warm | D3: Oyster | E3: B61 | F3: O_B61 | G3: 35.547 | H3: 73.82 | I3: 54.05 | J3: 14.88 | K3: 35.465 | L3: 75.17 | M3: 50.24 | N3: 19.13 | P3: 45879 | Q3: 45879 | U3: 03 Jul 25 Moved scallops to boxes
A4: 1 | B4: 1 | C4: Warm | D4: Oyster | E4: B54 | F4: O_B54 | G4: 30.829 | H4: =IFERROR(INDEX('Tagging key'!D:D, MATCH(F4,'Tagging key'!C:C,0)),"") -> 72.75 | I4: =IFERROR(INDEX('Tagging key'!E:E, MATCH(F4,'Tagging key'!C:C,0)),"") -> 42.12 | J4: =IFERROR(INDEX('Tagging key'!F:F, MATCH(F4,'Tagging key'!C:C,0)),"") -> 16.44 | K4: 30.754 | L4: 67.887 | M4: 36.02 | N4: 11.71 | P4: 45877 | Q4: 45877
A5: 1 | B5: 1 | C5: Warm | D5: Oyster | E5: R42 | F5: O_R42 | G5: 32.083 | H5: =IFERROR(INDEX('Tagging key'!D:D, MATCH(F5,'Tagging key'!C:C,0)),"") -> 63.69 | I5: =IFERROR(INDEX('Tagging key'!E:E, MATCH(F5,'Tagging key'!C:C,0)),"") -> 53.55 | J5: =IFERROR(INDEX('Tagging key'!F:F, MATCH(F5,'Tagging key'!C:C,0)),"") -> 18.02 | K5: 32.183 | L5: 63.77 | M5: 53.09 | N5: 19.13 | P5: 45882 | Q5: 45882 | R5: 22.071
A6: 1 | B6: 2 | C6: Warm | D6: Oyster | E6: B68 | F6: O_B68 | G6: 20.537 | H6: =IFERROR(INDEX('Tagging key'!D:D, MATCH(F6,'Tagging key'!C:C,0)),"") -> 59.48 | I6: =IFERROR(INDEX('Tagging key'!E:E, MATCH(F6,'Tagging key'!C:C,0)),"") -> 42.39 | J6: =IFERROR(INDEX('Tagging key'!F:F, MATCH(F6,'Tagging key'!C:C,0)),"") -> 13.12 | K6: 20.258 | L6: 58.38 | M6: 39.17 | N6: 14.78 | P6: 45882 | Q6: 45882 | R6: 11.349
A7: 1 | B7: 2 | C7: Warm | D7: Oyster | E7: B65 | F7: O_B65 | G7: 87.494 | H7: =IFERROR(INDEX('Tagging key'!D:D, MATCH(F7,'Tagging key'!C:C,0)),"") -> 69.63 | I7: =IFERROR(INDEX('Tagging key'!E:E, MATCH(F7,'Tagging key'!C:C,0)),"") -> 70.35 | J7: =IFERROR(INDEX('Tagging key'!F:F, MATCH(F7,'Tagging key'!C:C,0)),"") -> 23.62 | K7: 86.667 | L7: 73.01 | M7: 64.85 | N7: 21.42 | P7: 45877 | Q7: 45877 | S7: Removed a double
A8: 1 | B8: 2 | C8: Warm | D8: Oyster | E8: B5 | F8: O_B5 | G8: 29.658 | H8: =IFERROR(INDEX('Tagging key'!D:D, MATCH(F8,'Tagging key'!C:C,0)),"") -> 72.69 | I8: =IFERROR(INDEX('Tagging key'!E:E, MATCH(F8,'Tagging key'!C:C,0)),"") -> 44.55 | J8: =IFERROR(INDEX('Tagging key'!F:F, MATCH(F8,'Tagging key'!C:C,0)),"") -> 14.49 | K8: 29.744 | L8: 71.61 | M8: 44.79 | N8: 16.88 | P8: 45879 | Q8: 45879 | S8: Was in box 3
A9: 1 | B9: 2 | C9: Warm | D9: Oyster | E9: B88 | F9: O_B88 | G9: 28.24 | H9: =IFERROR(INDEX('Tagging key'!D:D, MATCH(F9,'Tagging key'!C:C,0)),"") -> 66.35 | I9: =IFERROR(INDEX('Tagging key'!E:E, MATCH(F9,'Tagging key'!C:C,0)),"") -> 50.23 | J9: =IFERROR(INDEX('Tagging key'!F:F, MATCH(F9,'Tagging key'!C:C,0)),"") -> 14.63 | K9: 28.046 | L9: 65.13 | M9: 47.82 | N9: 17.97 | P9: 45879 | Q9: 45879
A10: 1 | B10: 3 | C10: Warm | D10: Oyster | E10: R49 | F10: O_R49 | G10: 33.59 | H10: =IFERROR(INDEX('Tagging key'!D:D, MATCH(F10,'Tagging key'!C:C,0)),"") -> 62.02 | I10: =IFERROR(INDEX('Tagging key'!E:E, MATCH(F10,'Tagging key'!C:C,0)),"") -> 43.46 | J10: =IFERROR(INDEX('Tagging key'!F:F, MATCH(F10,'Tagging key'!C:C,0)),"") -> 17.31 | K10: 33.459 | L10: 62.33 | M10: 44.03 | N10: 17.73 | P10: 45886 | Q10: 45886
A11: 1 | B11: 3 | C11: Warm | D11: Oyster | E11: W15 | F11: O_W15 | G11: 42.011 | H11: =IFERROR(INDEX('Tagging key'!D:D, MATCH(F11,'Tagging key'!C:C,0)),"") -> 76.48 | I11: =IFERROR(INDEX('Tagging key'!E:E, MATCH(F11,'Tagging key'!C:C,0)),"") -> 44.98 | J11: =IFERROR(INDEX('Tagging key'!F:F, MATCH(F11,'Tagging key'!C:C,0)),"") -> 20.4 | K11: 41.79 | L11: 70.64 | M11: 39.33 | N11: 14.93 | P11: 45877 | Q11: 45877
A12: 1 | B12: 3 | C12: Warm | D12: Oyster | E12: B92 | F12: O_B92 | G12: 29.664 | H12: =IFERROR(INDEX('Tagging key'!D:D, MATCH(F12,'Tagging key'!C:C,0)),"") -> 67.87 | I12: =IFERROR(INDEX('Tagging key'!E:E, MATCH(F12,'Tagging key'!C:C,0)),"") -> 51.68 | J12: =IFERROR(INDEX('Tagging key'!F:F, MATCH(F12,'Tagging key'!C:C,0)),"") -> 14.59 | K12: 29.542 | L12: 66.76 | M12: 46.35 | N12: 17.4 | P12: 45886 | Q12: 45886 | S12: Was in box 2
A13: 1 | B13: 3 | C13: Warm | D13: Oyster | E13: B91 | F13: O_B91 | G13: 34.233 | H13: =IFERROR(INDEX('Tagging key'!D:D, MATCH(F13,'Tagging key'!C:C,0)),"") -> 66.29 | I13: =IFERROR(INDEX('Tagging key'!E:E, MATCH(F13,'Tagging key'!C:C,0)),"") -> 47.34 | J13: =IFERROR(INDEX('Tagging key'!F:F, MATCH(F13,'Tagging key'!C:C,0)),"") -> 15.65 | K13: 34.229 | L13: 66.77 | M13: 48.18 | N13: 19.8 | P13: 45882 | Q13: 45882 | R13: 21.574
A14: 1 | B14: 4 | C14: Warm | D14: Mussel | E14: G30 | F14: M_G30 | G14: 82.3 | H14: =IFERROR(INDEX('Tagging key'!D:D, MATCH(F14,'Tagging key'!C:C,0)),"") -> 96 | I14: =IFERROR(INDEX('Tagging key'!E:E, MATCH(F14,'Tagging key'!C:C,0)),"") -> 46 | J14: =IFERROR(INDEX('Tagging key'!F:F, MATCH(F14,'Tagging key'!C:C,0)),"") -> 37 | K14: 82.115 | L14: 98.74 | M14: 47.44 | N14: 36.25 | P14: 45882 | Q14: 45882 | R14: 23.783
A15: 1 | B15: 4 | C15: Warm | D15: Mussel | E15: B31 | F15: M_B31 | G15: 41.288 | H15: =IFERROR(INDEX('Tagging key'!D:D, MATCH(F15,'Tagging key'!C:C,0)),"") -> 75.98 | I15: =IFERROR(INDEX('Tagging key'!E:E, MATCH(F15,'Tagging key'!C:C,0)),"") -> 40.25 | J15: =IFERROR(INDEX('Tagging key'!F:F, MATCH(F15,'Tagging key'!C:C,0)),"") -> 27.05 | K15: 41.254 | L15: 70.85 | M15: 33.99 | N15: 23.42 | P15: 45877 | Q15: 45877
A16: 1 | B16: 4 | C16: Warm | D16: Mussel | E16: B67 | F16: M_B67 | G16: 79.137 | H16: =IFERROR(INDEX('Tagging key'!D:D, MATCH(F16,'Tagging key'!C:C,0)),"") -> 92.37 | I16: =IFERROR(INDEX('Tagging key'!E:E, MATCH(F16,'Tagging key'!C:C,0)),"") -> 47.28 | J16: =IFERROR(INDEX('Tagging key'!F:F, MATCH(F16,'Tagging key'!C:C,0)),"") -> 34.01 | K16: 78.926 | L16: 94.2 | M16: 45.59 | N16: 37.21 | P16: 45879 | Q16: 45879
A17: 1 | B17: 4 | C17: Warm | D17: Mussel | E17: R28 | F17: M_R28 | G17: 37.579 | H17: =IFERROR(INDEX('Tagging key'!D:D, MATCH(F17,'Tagging key'!C:C,0)),"") -> 74.19 | I17: =IFERROR(INDEX('Tagging key'!E:E, MATCH(F17,'Tagging key'!C:C,0)),"") -> 38.65 | J17: =IFERROR(INDEX('Tagging key'!F:F, MATCH(F17,'Tagging key'!C:C,0)),"") -> 27.59 | K17: 38.648 | L17: 74.26 | M17: 34.49 | N17: 28.23 | P17: 45886 | Q17: 45886
A18: 1 | B18: 5 | C18: Warm | D18: Mussel | E18: R82 | F18: M_R82 | G18: 42.545 | H18: =IFERROR(INDEX('Tagging key'!D:D, MATCH(F18,'Tagging key'!C:C,0)),"") -> 81 | I18: =IFERROR(INDEX('Tagging key'!E:E, MATCH(F18,'Tagging key'!C:C,0)),"") -> 41 | J18: =IFERROR(INDEX('Tagging key'!F:F, MATCH(F18,'Tagging key'!C:C,0)),"") -> 28 | K18: 48.897 | L18: 82.36 | M18: 40.42 | N18: 28.98 | P18: 45879 | Q18: 45879
A19: 1 | B19: 5 | C19: Warm | D19: Mussel | E19: B52 | F19: M_B52 | G19: 41.808 | H19: =IFERROR(INDEX('Tagging key'!D:D, MATCH(F19,'Tagging key'!C:C,0)),"") -> 77.14 | I19: =IFERROR(INDEX('Tagging key'!E:E, MATCH(F19,'Tagging key'!C:C,0)),"") -> 41.67 | J19: =IFERROR(INDEX('Tagging key'!F:F, MATCH(F19,'Tagging key'!C:C,0)),"") -> 27.56 | K19: 42.925 | L19: 73.25 | M19: 33.22 | N19: 22.36 | P19: 45877 | Q19: 45877
A20: 1 | B20: 5 | C20: Warm | D20: Mussel | E20: B93 | F20: M_B93 | G20: 48.348 | H20: =IFERROR(INDEX('Tagging key'!D:D, MATCH(F20,'Tagging key'!C:C,0)),"") -> 77 | I20: =IFERROR(INDEX('Tagging key'!E:E, MATCH(F20,'Tagging key'!C:C,0)),"") -> 39 | J20: =IFERROR(INDEX('Tagging key'!F:F, MATCH(F20,'Tagging key'!C:C,0)),"") -> 31 | K20: 59.117 | L20: 78.35 | M20: 39.34 | N20: 31.23 | P20: 45882 | Q20: 45882 | R20: 26.2
A21: 1 | B21: 5 | C21: Warm | D21: Mussel | E21: G1 | F21: M_G1 | G21: 46.31 | H21: =IFERROR(INDEX('Tagging key'!D:D, MATCH(F21,'Tagging key'!C:C,0)),"") -> 78 | I21: =IFERROR(INDEX('Tagging key'!E:E, MATCH(F21,'Tagging key'!C:C,0)),"") -> 40 | J21: =IFERROR(INDEX('Tagging key'!F:F, MATCH(F21,'Tagging key'!C:C,0)),"") -> 26 | K21: 47.335 | L21: 81.04 | M21: 40.92 | N21: 26.14 | P21: 45886 | Q21: 45886
A22: 1 | B22: 6 | C22: Warm | D22: Mussel | E22: G51 | F22: M_G51 | G22: 23.08 | H22: =IFERROR(INDEX('Tagging key'!D:D, MATCH(F22,'Tagging key'!C:C,0)),"") -> 62.3 | I22: =IFERROR(INDEX('Tagging key'!E:E, MATCH(F22,'Tagging key'!C:C,0)),"") -> 34.5 | J22: =IFERROR(INDEX('Tagging key'!F:F, MATCH(F22,'Tagging key'!C:C,0)),"") -> 21.4 | K22: 23.276 | L22: 63.05 | M22: 34.99 | N22: 22.39 | P22: 45879 | Q22: 45879 | S22: B47 Died 7/10, replaced with G51
A23: 1 | B23: 6 | C23: Warm | D23: Mussel | E23: B51 | F23: M_B51 | G23: 45.984 | H23: =IFERROR(INDEX('Tagging key'!D:D, MATCH(F23,'Tagging key'!C:C,0)),"") -> 76.72 | I23: =IFERROR(INDEX('Tagging key'!E:E, MATCH(F23,'Tagging key'!C:C,0)),"") -> 42.05 | J23: =IFERROR(INDEX('Tagging key'!F:F, MATCH(F23,'Tagging key'!C:C,0)),"") -> 26.28 | K23: 46.108 | L23: 71.5 | M23: 36.06 | N23: 21.64 | P23: 45877 | Q23: 45877
A24: 1 | B24: 6 | C24: Warm | D24: Mussel | E24: B69 | F24: M_B69 | G24: 31.393 | H24: =IFERROR(INDEX('Tagging key'!D:D, MATCH(F24,'Tagging key'!C:C,0)),"") -> 68 | I24: =IFERROR(INDEX('Tagging key'!E:E, MATCH(F24,'Tagging key'!C:C,0)),"") -> 33 | J24: =IFERROR(INDEX('Tagging key'!F:F, MATCH(F24,'Tagging key'!C:C,0)),"") -> 26 | K24: 31.966 | L24: 69.74 | M24: 34.26 | N24: 26.15 | P24: 45882 | Q24: 45882 | R24: 11.113
A25: 1 | B25: 6 | C25: Warm | D25: Mussel | E25: B94 | F25: M_B94 | G25: 51.927 | H25: =IFERROR(INDEX('Tagging key'!D:D, MATCH(F25,'Tagging key'!C:C,0)),"") -> 79 | I25: =IFERROR(INDEX('Tagging key'!E:E, MATCH(F25,'Tagging key'!C:C,0)),"") -> 37 | J25: =IFERROR(INDEX('Tagging key'!F:F, MATCH(F25,'Tagging key'!C:C,0)),"") -> 32 | K25: 52.339 | L25: 79.34 | M25: 37.27 | N25: 32.94 | P25: 45886 | Q25: 45886
A26: 1 | B26: 7 | C26: Warm | D26: Scallop | E26: Y32 | F26: S_Y32 | G26: 50.988 | H26: =IFERROR(INDEX('Tagging key'!D:D, MATCH(F26,'Tagging key'!C:C,0)),"") -> 69 | I26: =IFERROR(INDEX('Tagging key'!E:E, MATCH(F26,'Tagging key'!C:C,0)),"") -> 71.5 | J26: =IFERROR(INDEX('Tagging key'!F:F, MATCH(F26,'Tagging key'!C:C,0)),"") -> 18 | K26: 46.064 | L26: 69.92 | M26: 73.16 | N26: 21 | P26: 45882 | Q26: 45882 | R26: 23.565
A27: 1 | B27: 7 | C27: Warm | D27: Scallop | E27: G70 | F27: S_G70 | G27: 50.64 | H27: =IFERROR(INDEX('Tagging key'!D:D, MATCH(F27,'Tagging key'!C:C,0)),"") -> 71 | I27: =IFERROR(INDEX('Tagging key'!E:E, MATCH(F27,'Tagging key'!C:C,0)),"") -> 73 | J27: =IFERROR(INDEX('Tagging key'!F:F, MATCH(F27,'Tagging key'!C:C,0)),"") -> 20 | K27: 40.579 | L27: 70.88 | M27: 74.32 | N27: 21.2 | P27: 45886 | Q27: 45886 | S27: Was in as G79
A28: 1 | B28: 7 | C28: Warm | D28: Scallop | E28: Y54 | F28: S_Y54 | G28: 57.49 | H28: =IFERROR(INDEX('Tagging key'!D:D, MATCH(F28,'Tagging key'!C:C,0)),"") -> 71.5 | I28: =IFERROR(INDEX('Tagging key'!E:E, MATCH(F28,'Tagging key'!C:C,0)),"") -> 75.5 | J28: =IFERROR(INDEX('Tagging key'!F:F, MATCH(F28,'Tagging key'!C:C,0)),"") -> 20 | K28: 55.155 | L28: 73.62 | M28: 78.32 | N28: 23.12 | P28: 45879 | Q28: 45879 | R28: 20.813
A29: 1 | B29: 7 | C29: Warm | D29: Scallop | E29: Y74 | F29: S_Y74 | G29: 46.17 | H29: =IFERROR(INDEX('Tagging key'!D:D, MATCH(F29,'Tagging key'!C:C,0)),"") -> 66 | I29: =IFERROR(INDEX('Tagging key'!E:E, MATCH(F29,'Tagging key'!C:C,0)),"") -> 70 | J29: =IFERROR(INDEX('Tagging key'!F:F, MATCH(F29,'Tagging key'!C:C,0)),"") -> 17 | K29: 43.563 | L29: 63.06 | M29: 65.51 | N29: 14.5 | P29: 45877 | Q29: 45877
A30: 1 | B30: 8 | C30: Warm | D30: Scallop | E30: Y71 | F30: S_Y71 | G30: 70.19 | H30: =IFERROR(INDEX('Tagging key'!D:D, MATCH(F30,'Tagging key'!C:C,0)),"") -> 77 | I30: =IFERROR(INDEX('Tagging key'!E:E, MATCH(F30,'Tagging key'!C:C,0)),"") -> 80 | J30: =IFERROR(INDEX('Tagging key'!F:F, MATCH(F30,'Tagging key'!C:C,0)),"") -> 20 | K30: 66.168 | L30: 78.34 | M30: 81.95 | N30: 22.6 | P30: 45882 | Q30: 45882 | R30: 33.409
A31: 1 | B31: 8 | C31: Warm | D31: Scallop | E31: W57 | F31: S_W57 | G31: 43.73 | H31: =IFERROR(INDEX('Tagging key'!D:D, MATCH(F31,'Tagging key'!C:C,0)),"") -> 67 | I31: =IFERROR(INDEX('Tagging key'!E:E, MATCH(F31,'Tagging key'!C:C,0)),"") -> 70 | J31: =IFERROR(INDEX('Tagging key'!F:F, MATCH(F31,'Tagging key'!C:C,0)),"") -> 13 | K31: 40.048 | L31: 67.84 | M31: 71.9 | N31: 17.36 | P31: 45886 | Q31: 45886
A32: 1 | B32: 8 | C32: Warm | D32: Scallop | E32: G37 | F32: S_G37 | G32: 45.28 | H32: =IFERROR(INDEX('Tagging key'!D:D, MATCH(F32,'Tagging key'!C:C,0)),"") -> 69.62 | I32: =IFERROR(INDEX('Tagging key'!E:E, MATCH(F32,'Tagging key'!C:C,0)),"") -> 70.99 | J32: =IFERROR(INDEX('Tagging key'!F:F, MATCH(F32,'Tagging key'!C:C,0)),"") -> 17.56 | K32: 43.895 | L32: 66.21 | M32: 69.48 | N32: 14.26 | P32: 45877 | Q32: 45877
A33: 1 | B33: 8 | C33: Warm | D33: Scallop | E33: G50 | F33: S_G50 | G33: 46.96 | H33: =IFERROR(INDEX('Tagging key'!D:D, MATCH(F33,'Tagging key'!C:C,0)),"") -> 76 | I33: =IFERROR(INDEX('Tagging key'!E:E, MATCH(F33,'Tagging key'!C:C,0)),"") -> 74 | J33: =IFERROR(INDEX('Tagging key'!F:F, MATCH(F33,'Tagging key'!C:C,0)),"") -> 16.54 | K33: 43.487 | L33: 72.25 | M33: 70.2 | N33: 19 | P33: 45879 | Q33: 45879
A34: 1 | B34: 9 | C34: Warm | D34: Scallop | E34: B3 | F34: S_B3 | H34: =IFERROR(INDEX('Tagging key'!D:D, MATCH(F34,'Tagging key'!C:C,0)),"") | I34: =IFERROR(INDEX('Tagging key'!E:E, MATCH(F34,'Tagging key'!C:C,0)),"") | J34: =IFERROR(INDEX('Tagging key'!F:F, MATCH(F34,'Tagging key'!C:C,0)),"") | K34: 63.925 | L34: 74.74 | M34: 79.15 | N34: 15.8 | P34: 45877 | Q34: 45877 | S34: Y10 Died 7/10 | T34: G55B Died 7/14
A35: 1 | B35: 9 | C35: Warm | D35: Scallop | E35: B4 | F35: S_B4 | H35: =IFERROR(INDEX('Tagging key'!D:D, MATCH(F35,'Tagging key'!C:C,0)),"") | I35: =IFERROR(INDEX('Tagging key'!E:E, MATCH(F35,'Tagging key'!C:C,0)),"") | J35: =IFERROR(INDEX('Tagging key'!F:F, MATCH(F35,'Tagging key'!C:C,0)),"") | K35: 64.118 | L35: 79.66 | M35: 84.5 | N35: 21.52 | P35: 45879 | Q35: 45879 | S35: Y93 Died 7/10 | T35: G46B Died 7/14
A36: 1 | B36: 9 | C36: Warm | D36: Scallop | E36: B2 | F36: S_B2 | H36: =IFERROR(INDEX('Tagging key'!D:D, MATCH(F36,'Tagging key'!C:C,0)),"") | I36: =IFERROR(INDEX('Tagging key'!E:E, MATCH(F36,'Tagging key'!C:C,0)),"") | J36: =IFERROR(INDEX('Tagging key'!F:F, MATCH(F36,'Tagging key'!C:C,0)),"") | K36: 48.91 | L36: 71.35 | M36: 75.45 | N36: 19.71 | P36: 45882 | Q36: 45882 | S36: G34 Died 7/13
A37: 1 | B37: 9 | C37: Warm | D37: Scallop | E37: B1 | F37: S_B1 | H37: =IFERROR(INDEX('Tagging key'!D:D, MATCH(F37,'Tagging key'!C:C,0)),"") | I37: =IFERROR(INDEX('Tagging key'!E:E, MATCH(F37,'Tagging key'!C:C,0)),"") | J37: =IFERROR(INDEX('Tagging key'!F:F, MATCH(F37,'Tagging key'!C:C,0)),"") | K37: 57.301 | L37: 75.94 | M37: 81.98 | N37: 23 | P37: 45886 | Q37: 45886 | S37: G62 Died 7/10 | T37: G45B Died 7/13
A38: 2 | B38: 1 | C38: Multi | D38: Oyster | E38: W4 | F38: O_W4 | G38: 27.457 | H38: 66.92 | I38: 40.6 | J38: 14.18 | K38: 27.447 | L38: 66.41 | M38: 40.3 | N38: 15.3 | P38: 45886 | Q38: 45886
A39: 2 | B39: 1 | C39: Multi | D39: Oyster | E39: B100 | F39: O_B100 | G39: 28.461 | H39: =IFERROR(INDEX('Tagging key'!D:D, MATCH(F39,'Tagging key'!C:C,0)),"") -> 60 | I39: =IFERROR(INDEX('Tagging key'!E:E, MATCH(F39,'Tagging key'!C:C,0)),"") -> 48.92 | J39: =IFERROR(INDEX('Tagging key'!F:F, MATCH(F39,'Tagging key'!C:C,0)),"") -> 17.08 | K39: 28.301 | L39: 61 | M39: 46.24 | N39: 18.86 | P39: 45882 | Q39: 45882 | R39: 19.264
A40: 2 | B40: 1 | C40: Multi | D40: Oyster | E40: W48 | F40: O_W48 | G40: 36.899 | H40: =IFERROR(INDEX('Tagging key'!D:D, MATCH(F40,'Tagging key'!C:C,0)),"") -> 73.26 | I40: =IFERROR(INDEX('Tagging key'!E:E, MATCH(F40,'Tagging key'!C:C,0)),"") -> 50.23 | J40: =IFERROR(INDEX('Tagging key'!F:F, MATCH(F40,'Tagging key'!C:C,0)),"") -> 15.63 | K40: 36.508 | L40: 75.48 | M40: 49.99 | N40: 29.37 | P40: 45879 | Q40: 45879
...

Sheet Tagging key
A1: Species | B1: BeeTag ID | C1: Unique_ID | D1: Length (mm) | E1: Width (mm) | F1: Height (mm) | G1: Comment
A2: Oyster | B2: R1 | C2: O_R1 | D2: 62.07 | E2: 51.41 | F2: 20.09 | K2: Missing tags R5 & R6
A3: Oyster | B3: R2 | C3: O_R2 | D3: 64.94 | E3: 59.78 | F3: 19.65 | G3: Died before expt | K3: R18 & R40 was dead when labeled
A4: Oyster | B4: R3 | C4: O_R3 | D4: 69.3 | E4: 44.51 | F4: 16.88 | K4: B79 & B93 was dead when labeled
A5: Oyster | B5: R4 | C5: O_R4 | D5: 68.27 | E5: 41.27 | F5: 20.03 | K5: LABEL Y7 & Y84 WAS LOST
A6: Oyster | B6: R7 | C6: O_R7 | D6: 80.42 | E6: 47.66 | F6: 19.63 | K6: Died before expt:
A7: Oyster | B7: R8 | C7: O_R8 | D7: 62.28 | E7: 34.51 | F7: 17.47 | K7: Oyster | L7: R2
A8: Oyster | B8: R9 | C8: O_R9 | D8: 63.26 | E8: 47.67 | F8: 14.78 | K8: Oyster | L8: B37
A9: Oyster | B9: R10 | C9: O_R10 | D9: 60.77 | E9: 43.41 | F9: 17.54 | K9: Oyster | L9: B75
A10: Oyster | B10: R11 | C10: O_R11 | D10: 77.87 | E10: 46.75 | F10: 15.61 | K10: Oyster | L10: W43
A11: Oyster | B11: R12 | C11: O_R12 | D11: 65.48 | E11: 44.69 | F11: 16.56
A12: Oyster | B12: R13 | C12: O_R13 | D12: 61.21 | E12: 42.25 | F12: 14.03
A13: Oyster | B13: R14 | C13: O_R14 | D13: 60.29 | E13: 43.41 | F13: 16.24
A14: Oyster | B14: R15 | C14: O_R15 | D14: 58.87 | E14: 53.72 | F14: 15.89
A15: Oyster | B15: R16 | C15: O_R16 | D15: 64.75 | E15: 44.36 | F15: 20.89
A16: Oyster | B16: R17 | C16: O_R17 | D16: 78.06 | E16: 55.62 | F16: 27.44
A17: Oyster | B17: R19 | C17: O_R19 | D17: 66.74 | E17: 44.98 | F17: 13.67
A18: Oyster | B18: R20 | C18: O_R20 | D18: 65 | E18: 43.53 | F18: 16.92
A19: Oyster | B19: R21 | C19: O_R21 | D19: 53.55 | E19: 49.5 | F19: 13.77
A20: Oyster | B20: R22 | C20: O_R22 | D20: 69.94 | E20: 48.94 | F20: 19.08
A21: Oyster | B21: R23 | C21: O_R23 | D21: 61.89 | E21: 57.9 | F21: 23.35
A22: Oyster | B22: R24 | C22: O_R24 | D22: 58.57 | E22: 39.39 | F22: 19.2
... A34: Oyster | B34: R36 | C34: O_R36 | D34: 76.53 | E34: 47.91 | F34: 17.82
A35: Oyster | B35: R37 | C35: O_R37 | D35: 61.11 | E35: 46.57 | F35: 18.88 | G35: rounded the length out for measurement. Slightly angled
A36: Oyster | B36: R38 | C36: O_R38 | D36: 59.54 | E36: 42.86 | F36: 15.87
A37: Oyster | B37: R39 | C37: O_R39 | D37: 68 | E37: 49.71 | F37: 17.42
A38: Oyster | B38: R41 | C38: O_R41 | D38: 67.97 | E38: 44.12 | F38: 19.17
A39: Oyster | B39: R42 | C39: O_R42 | D39: 63.69 | E39: 53.55 | F39: 18.02
A40: Oyster | B40: R43 | C40: O_R43 | D40: 81.28 | E40: 51.86 | F40: 23.17
A41: Oyster | B41: R44 | C41: O_R44 | D41: 80.14 | E41: 50.61 | F41: 20.72
A42: Oyster | B42: R45 | C42: O_R45 | D42: 70.91 | E42: 53.97 | F42: 17.24
A43: Oyster | B43: R46 | C43: O_R46 | D43: 60.92 | E43: 44.39 | F43: 18.02
A44: Oyster | B44: R47 | C44: O_R47 | D44: 66.75 | E44: 48.68 | F44: 17.59
A45: Oyster | B45: R48 | C45: O_R48 | D45: 67.45 | E45: 62.01 | F45: 14.2
A46: Oyster | B46: R49 | C46: O_R49 | D46: 62.02 | E46: 43.46 | F46: 17.31
A47: Oyster | B47: R50 | C47: O_R50 | D47: 68.14 | E47: 54.19 | F47: 20.58
... A133: Oyster | B133: B36 | C133: O_B36 | D133: 64.04 | E133: 42.84 | F133: 16.26
A134: Oyster | B134: B37 | C134: O_B37 | D134: 63.03 | E134: 52.65 | F134: 18.17 | G134: Died before expt
A135: Oyster | B135: B38 | C135: O_B38 | D135: 62.48 | E135: 47.16 | F135: 14.17
A136: Oyster | B136: B39 | C136: O_B39 | D136: 77.97 | E136: 40.86 | F136: 17.27
...

Sheet Feeding
A1: Tank | B1: Box | C1: Bee Tag | D1: Diet
A2: 1 | B2: 1 | C2: O_B_54
A3: 1 | B3: 2 | C3: O_B_65
A4: 1 | B4: 3 | C4: O_W_15
A5: 1 | B5: 4 | C5: M_B_31
A6: 1 | B6: 5 | C6: M_B_52
A7: 1 | B7: 6 | C7: M_B_51
A8: 1 | B8: 7 | C8: S_Y_74
A9: 1 | B9: 8 | C9: S_G_37
A10: 1 | B10: 9 | C10: S_B_3
A11: 2 | B11: 1 | C11: O_B_34
A12: 2 | B12: 2 | C12: O_W_16
A13: 2 | B13: 3 | C13: O_B_89
... A44: 5 | B44: 7 | C44: M_B_8
A45: 5 | B45: 8 | C45: M_B_18 | D45: ALIVE BUT CAME FROM ONE WITH A DEAD ONE
A46: 5 | B46: 9 | C46: M_R_42
A47: 6 | B47: 1 | C47: S_G53
A48: 6 | B48: 2 | C48: S_Y13
A49: 6 | B49: 3 | C49: S_Y61
A50: 6 | B50: 4 | C50: M_R6
A51: 6 | B51: 5 | C51: M_B37
A52: 6 | B52: 6 | C52: M_B6
A53: 6 | B53: 7 | C53: O_R43 | D53: b24 dead
A54: 6 | B54: 8 | C54: O_B25
A55: 6 | B55: 9 | C55: O_R30
A56: 7 | B56: 1 | C56: M_R35
A57: 7 | B57: 2 | C57: M_G12
A58: 7 | B58: 3 | C58: M_R69
A59: 7 | B59: 4 | C59: S_W99
A60: 7 | B60: 5 | C60: S_W84
A61: 7 | B61: 6 | C61: S_W75
A62: 7 | B62: 7 | C62: O_B69
A63: 7 | B63: 8 | C63: O_B7
A64: 7 | B64: 9 | C64: O_R36
A65: 8 | B65: 1 | C65: O_B49
... A181: 20 | B181: 9 | C181: M_B_27
